Workbook

Sheet Items
A1: Item | B1: Item ID (game) | C1: Category | D1: Importer(s) (* = only with "all products" setting) | E1: Import Price ($/unit) | F1: Avg Selling Price ($/unit) | G1: Gross Profit ($/unit) | H1: Gross Margin % | I1: Units per Box | J1: Cost per Box ($) | K1: Max Import Order / Importer / Week | L1: Can Be Made in Factory? | M1: Used as Factory Input? | N1: Sold By (business types)
A2: Baking Mix | B2: ba:itemname_bakingmix | C2: Raw Material | D2: Lunar Tide Shipments | E2: 0.1 | G2: =IF(AND(ISNUMBER(E2),ISNUMBER(F2)),F2-E2,"") | H2: =IF(AND(ISNUMBER(G2),N(F2)>0),G2/F2,"") | I2: 500 | J2: =IF(AND(ISNUMBER(E2),ISNUMBER(I2)),E2*I2,"") -> 50 | K2: 5000 | L2: No | M2: Yes
A3: Barley | B3: ba:itemname_barley | C3: Raw Material | D3: Aquatic Bay Cargo | E3: 0.24 | G3: =IF(AND(ISNUMBER(E3),ISNUMBER(F3)),F3-E3,"") | H3: =IF(AND(ISNUMBER(G3),N(F3)>0),G3/F3,"") | I3: 500 | J3: =IF(AND(ISNUMBER(E3),ISNUMBER(I3)),E3*I3,"") -> 120 | K3: 5000 | L3: No | M3: Yes
A4: Battery | B4: ba:itemname_battery | C4: Raw Material | D4: Maritime Freight Line | E4: 16 | G4: =IF(AND(ISNUMBER(E4),ISNUMBER(F4)),F4-E4,"") | H4: =IF(AND(ISNUMBER(G4),N(F4)>0),G4/F4,"") | I4: 500 | J4: =IF(AND(ISNUMBER(E4),ISNUMBER(I4)),E4*I4,"") -> 8000 | K4: 5000 | L4: No | M4: Yes
A5: Blue Agave | B5: ba:itemname_blueagave | C5: Raw Material | D5: Aquatic Bay Cargo | E5: 0.12 | G5: =IF(AND(ISNUMBER(E5),ISNUMBER(F5)),F5-E5,"") | H5: =IF(AND(ISNUMBER(G5),N(F5)>0),G5/F5,"") | I5: 500 | J5: =IF(AND(ISNUMBER(E5),ISNUMBER(I5)),E5*I5,"") -> 60 | K5: 5000 | L5: No | M5: Yes
A6: Butter | B6: ba:itemname_butter | C6: Raw Material | D6: Lunar Tide Shipments | E6: 0.5 | G6: =IF(AND(ISNUMBER(E6),ISNUMBER(F6)),F6-E6,"") | H6: =IF(AND(ISNUMBER(G6),N(F6)>0),G6/F6,"") | I6: 500 | J6: =IF(AND(ISNUMBER(E6),ISNUMBER(I6)),E6*I6,"") -> 250 | K6: 5000 | L6: No | M6: Yes
A7: Caffeine Extract | B7: ba:itemname_caffeineextract | C7: Raw Material | D7: Aquatic Bay Cargo | E7: 0.1 | G7: =IF(AND(ISNUMBER(E7),ISNUMBER(F7)),F7-E7,"") | H7: =IF(AND(ISNUMBER(G7),N(F7)>0),G7/F7,"") | I7: 500 | J7: =IF(AND(ISNUMBER(E7),ISNUMBER(I7)),E7*I7,"") -> 50 | K7: 5000 | L7: No | M7: Yes
A8: Capacitors | B8: ba:itemname_capacitors | C8: Raw Material | D8: Maritime Freight Line | E8: 6 | G8: =IF(AND(ISNUMBER(E8),ISNUMBER(F8)),F8-E8,"") | H8: =IF(AND(ISNUMBER(G8),N(F8)>0),G8/F8,"") | I8: 1000 | J8: =IF(AND(ISNUMBER(E8),ISNUMBER(I8)),E8*I8,"") -> 6000 | K8: 5000 | L8: No | M8: Yes
A9: Carbon Dioxide | B9: ba:itemname_carbondioxide | C9: Raw Material | D9: Aquatic Bay Cargo | E9: 0.01 | G9: =IF(AND(ISNUMBER(E9),ISNUMBER(F9)),F9-E9,"") | H9: =IF(AND(ISNUMBER(G9),N(F9)>0),G9/F9,"") | I9: 500 | J9: =IF(AND(ISNUMBER(E9),ISNUMBER(I9)),E9*I9,"") -> 5 | K9: 5000 | L9: No | M9: Yes
A10: Cheese | B10: ba:itemname_cheese | C10: Raw Material | D10: Lunar Tide Shipments | E10: 0.32 | G10: =IF(AND(ISNUMBER(E10),ISNUMBER(F10)),F10-E10,"") | H10: =IF(AND(ISNUMBER(G10),N(F10)>0),G10/F10,"") | I10: 500 | J10: =IF(AND(ISNUMBER(E10),ISNUMBER(I10)),E10*I10,"") -> 160 | K10: 5000 | L10: No | M10: Yes
A11: Chicken Breast | B11: ba:itemname_chickenbreast | C11: Raw Material | D11: Lunar Tide Shipments | E11: 0.35 | G11: =IF(AND(ISNUMBER(E11),ISNUMBER(F11)),F11-E11,"") | H11: =IF(AND(ISNUMBER(G11),N(F11)>0),G11/F11,"") | I11: 500 | J11: =IF(AND(ISNUMBER(E11),ISNUMBER(I11)),E11*I11,"") -> 175 | K11: 5000 | L11: No | M11: Yes
A12: Cigar Paper | B12: ba:itemname_cigarpaper | C12: Raw Material | D12: Global Harvest Traders | E12: 1 | G12: =IF(AND(ISNUMBER(E12),ISNUMBER(F12)),F12-E12,"") | H12: =IF(AND(ISNUMBER(G12),N(F12)>0),G12/F12,"") | I12: 1000 | J12: =IF(AND(ISNUMBER(E12),ISNUMBER(I12)),E12*I12,"") -> 1000 | K12: 5000 | L12: No | M12: Yes
A13: Cigarette Paper | B13: ba:itemname_cigarettepaper | C13: Raw Material | D13: Global Harvest Traders | E13: 0.5 | G13: =IF(AND(ISNUMBER(E13),ISNUMBER(F13)),F13-E13,"") | H13: =IF(AND(ISNUMBER(G13),N(F13)>0),G13/F13,"") | I13: 1000 | J13: =IF(AND(ISNUMBER(E13),ISNUMBER(I13)),E13*I13,"") -> 500 | K13: 5000 | L13: No | M13: Yes
... A60: Yeast | B60: ba:itemname_yeast | C60: Raw Material | D60: Aquatic Bay Cargo | E60: 0.01 | G60: =IF(AND(ISNUMBER(E60),ISNUMBER(F60)),F60-E60,"") | H60: =IF(AND(ISNUMBER(G60),N(F60)>0),G60/F60,"") | I60: 500 | J60: =IF(AND(ISNUMBER(E60),ISNUMBER(I60)),E60*I60,"") -> 5 | K60: 5000 | L60: No | M60: Yes
A61: Bag of Lettuce | B61: ba:itemname_lettuce | C61: Finished Good (also raw input) | D61: Lunar Tide Shipments, SeaSide Internationals | E61: 0.28 | F61: 2.12 | G61: =IF(AND(ISNUMBER(E61),ISNUMBER(F61)),F61-E61,"") -> 1.84 | H61: =IF(AND(ISNUMBER(G61),N(F61)>0),G61/F61,"") -> 0.86792453 | I61: 250 | J61: =IF(AND(ISNUMBER(E61),ISNUMBER(I61)),E61*I61,"") -> 70 | K61: 25000 | L61: Yes | M61: Yes | N61: Supermarket, Fruit And Vegetable Store
A62: Bag of Tomatoes | B62: ba:itemname_tomato | C62: Finished Good (also raw input) | D62: Lunar Tide Shipments, SeaSide Internationals | E62: 0.29 | F62: 2.56 | G62: =IF(AND(ISNUMBER(E62),ISNUMBER(F62)),F62-E62,"") -> 2.27 | H62: =IF(AND(ISNUMBER(G62),N(F62)>0),G62/F62,"") -> 0.88671875 | I62: 500 | J62: =IF(AND(ISNUMBER(E62),ISNUMBER(I62)),E62*I62,"") -> 145 | K62: 25000 | L62: Yes | M62: Yes | N62: Supermarket, Fruit And Vegetable Store
A63: Arty Fish Phone | B63: ba:itemname_smartphone1 | C63: Finished Good | D63: BlueStone Imports* | E63: 350 | F63: 799 | G63: =IF(AND(ISNUMBER(E63),ISNUMBER(F63)),F63-E63,"") -> 449 | H63: =IF(AND(ISNUMBER(G63),N(F63)>0),G63/F63,"") -> 0.56195244 | I63: 300 | J63: =IF(AND(ISNUMBER(E63),ISNUMBER(I63)),E63*I63,"") -> 105000 | K63: 7500 | L63: Yes | M63: No | N63: Electronics Store
A64: Arty Fish Smartwatch | B64: ba:itemname_smartwatch2 | C64: Finished Good | D64: BlueStone Imports* | E64: 150 | F64: 324 | G64: =IF(AND(ISNUMBER(E64),ISNUMBER(F64)),F64-E64,"") -> 174 | H64: =IF(AND(ISNUMBER(G64),N(F64)>0),G64/F64,"") -> 0.53703704 | I64: 300 | J64: =IF(AND(ISNUMBER(E64),ISNUMBER(I64)),E64*I64,"") -> 45000 | K64: 7500 | L64: Yes | M64: No | N64: Gift Shop, Electronics Store, Jewelry Store
A65: Bag of Apples | B65: ba:itemname_apple | C65: Finished Good | D65: SeaSide Internationals | E65: 0.32 | F65: 2.89 | G65: =IF(AND(ISNUMBER(E65),ISNUMBER(F65)),F65-E65,"") -> 2.57 | H65: =IF(AND(ISNUMBER(G65),N(F65)>0),G65/F65,"") -> 0.88927336 | I65: 500 | J65: =IF(AND(ISNUMBER(E65),ISNUMBER(I65)),E65*I65,"") -> 160 | K65: 25000 | L65: Yes | M65: No | N65: Supermarket, Fast Food Restaurant, Coffee Shop, Fruit And Vegetable Store
A66: Bag of Bananas | B66: ba:itemname_banana | C66: Finished Good | D66: SeaSide Internationals | E66: 0.26 | F66: 2.35 | G66: =IF(AND(ISNUMBER(E66),ISNUMBER(F66)),F66-E66,"") -> 2.09 | H66: =IF(AND(ISNUMBER(G66),N(F66)>0),G66/F66,"") -> 0.8893617 | I66: 500 | J66: =IF(AND(ISNUMBER(E66),ISNUMBER(I66)),E66*I66,"") -> 130 | K66: 25000 | L66: Yes | M66: No | N66: Supermarket, Fast Food Restaurant, Coffee Shop, Fruit And Vegetable Store
A67: Bag of Carrots | B67: ba:itemname_carrot | C67: Finished Good | D67: SeaSide Internationals | E67: 0.28 | F67: 2.24 | G67: =IF(AND(ISNUMBER(E67),ISNUMBER(F67)),F67-E67,"") -> 1.96 | H67: =IF(AND(ISNUMBER(G67),N(F67)>0),G67/F67,"") -> 0.875 | I67: 500 | J67: =IF(AND(ISNUMBER(E67),ISNUMBER(I67)),E67*I67,"") -> 140 | K67: 25000 | L67: Yes | M67: No | N67: Supermarket, Fruit And Vegetable Store
A68: Bag of Pears | B68: ba:itemname_pear | C68: Finished Good | D68: SeaSide Internationals | E68: 0.29 | F68: 2.62 | G68: =IF(AND(ISNUMBER(E68),ISNUMBER(F68)),F68-E68,"") -> 2.33 | H68: =IF(AND(ISNUMBER(G68),N(F68)>0),G68/F68,"") -> 0.88931298 | I68: 500 | J68: =IF(AND(ISNUMBER(E68),ISNUMBER(I68)),E68*I68,"") -> 145 | K68: 25000 | L68: Yes | M68: No | N68: Supermarket, Fruit And Vegetable Store
A69: Beer | B69: ba:itemname_beer | C69: Finished Good | D69: United Ocean Import | E69: 2 | F69: 12 | G69: =IF(AND(ISNUMBER(E69),ISNUMBER(F69)),F69-E69,"") -> 10 | H69: =IF(AND(ISNUMBER(G69),N(F69)>0),G69/F69,"") -> 0.83333333 | I69: 300 | J69: =IF(AND(ISNUMBER(E69),ISNUMBER(I69)),E69*I69,"") -> 600 | K69: 15000 | L69: Yes | M69: No | N69: Liquor Store, Nightclub
A70: Bottle of Wine | B70: ba:itemname_bottleofwine | C70: Finished Good | D70: United Ocean Import | E70: 5.8 | F70: 21 | G70: =IF(AND(ISNUMBER(E70),ISNUMBER(F70)),F70-E70,"") -> 15.2 | H70: =IF(AND(ISNUMBER(G70),N(F70)>0),G70/F70,"") -> 0.72380952 | I70: 300 | J70: =IF(AND(ISNUMBER(E70),ISNUMBER(I70)),E70*I70,"") -> 1740 | K70: 15000 | L70: Yes | M70: No | N70: Liquor Store, Supermarket
A71: Burger | B71: ba:itemname_burger | C71: Finished Good | D71: JetCargo Imports | E71: 4.75 | F71: 12.5 | G71: =IF(AND(ISNUMBER(E71),ISNUMBER(F71)),F71-E71,"") -> 7.75 | H71: =IF(AND(ISNUMBER(G71),N(F71)>0),G71/F71,"") -> 0.62 | I71: 500 | J71: =IF(AND(ISNUMBER(E71),ISNUMBER(I71)),E71*I71,"") -> 2375 | K71: 25000 | L71: Yes | M71: No | N71: Fast Food Restaurant
A72: Cheese Platter | B72: ba:itemname_cheeseplatter | C72: Finished Good | D72: United Ocean Import | E72: 1 | F72: 15 | G72: =IF(AND(ISNUMBER(E72),ISNUMBER(F72)),F72-E72,"") -> 14 | H72: =IF(AND(ISNUMBER(G72),N(F72)>0),G72/F72,"") -> 0.93333333 | I72: 500 | J72: =IF(AND(ISNUMBER(E72),ISNUMBER(I72)),E72*I72,"") -> 500 | K72: 25000 | L72: Yes | M72: No | N72: Theater
... A121: ZanaMan Smartwatch | B121: ba:itemname_smartwatch1 | C121: Finished Good | D121: BlueStone Imports* | E121: 250 | F121: 399 | G121: =IF(AND(ISNUMBER(E121),ISNUMBER(F121)),F121-E121,"") -> 149 | H121: =IF(AND(ISNUMBER(G121),N(F121)>0),G121/F121,"") -> 0.37343358 | I121: 300 | J121: =IF(AND(ISNUMBER(E121),ISNUMBER(I121)),E121*I121,"") -> 75000 | K121: 7500 | L121: Yes | M121: No | N121: Gift Shop, Electronics Store, Jewelry Store
A122: Cinema Ticket | B122: ba:itemname_cinematicket | C122: Service | D122: n/a (service) | F122: 16 | G122: =IF(AND(ISNUMBER(E122),ISNUMBER(F122)),F122-E122,"") | H122: =IF(AND(ISNUMBER(G122),N(F122)>0),G122/F122,"") | J122: =IF(AND(ISNUMBER(E122),ISNUMBER(I122)),E122*I122,"") | L122: No | M122: No | N122: Cinema
A123: Coat Check Fee | B123: ba:itemname_coatcheckfee | C123: Service | D123: n/a (service) | F123: 5 | G123: =IF(AND(ISNUMBER(E123),ISNUMBER(F123)),F123-E123,"") | H123: =IF(AND(ISNUMBER(G123),N(F123)>0),G123/F123,"") | J123: =IF(AND(ISNUMBER(E123),ISNUMBER(I123)),E123*I123,"") | L123: No | M123: No | N123: Nightclub
A124: Event Planning Fee (Hourly) | B124: ba:itemname_hourlyeventplanningfee | C124: Service | D124: n/a (service) | F124: 150 | G124: =IF(AND(ISNUMBER(E124),ISNUMBER(F124)),F124-E124,"") | H124: =IF(AND(ISNUMBER(G124),N(F124)>0),G124/F124,"") | J124: =IF(AND(ISNUMBER(E124),ISNUMBER(I124)),E124*I124,"") | L124: No | M124: No | N124: Event Planning Agency
A125: Graphic Designer Fee (Hourly) | B125: ba:itemname_hourlygraphicdesignerfee | C125: Service | D125: n/a (service) | F125: 160 | G125: =IF(AND(ISNUMBER(E125),ISNUMBER(F125)),F125-E125,"") | H125: =IF(AND(ISNUMBER(G125),N(F125)>0),G125/F125,"") | J125: =IF(AND(ISNUMBER(E125),ISNUMBER(I125)),E125*I125,"") | L125: No | M125: No | N125: Graphic Designer
A126: Gym Cover Charge | B126: ba:itemname_gymcovercharge | C126: Service | D126: n/a (service) | F126: 20 | G126: =IF(AND(ISNUMBER(E126),ISNUMBER(F126)),F126-E126,"") | H126: =IF(AND(ISNUMBER(G126),N(F126)>0),G126/F126,"") | J126: =IF(AND(ISNUMBER(E126),ISNUMBER(I126)),E126*I126,"") | L126: No | M126: No | N126: Gym
A127: Hair Chemical / Color Fee | B127: ba:itemname_hairchemicalfee | C127: Service | D127: n/a (service) | F127: 150 | G127: =IF(AND(ISNUMBER(E127),ISNUMBER(F127)),F127-E127,"") | H127: =IF(AND(ISNUMBER(G127),N(F127)>0),G127/F127,"") | J127: =IF(AND(ISNUMBER(E127),ISNUMBER(I127)),E127*I127,"") | L127: No | M127: No | N127: Hairdresser
A128: Hair Cutting Fee | B128: ba:itemname_haircuttingfee | C128: Service | D128: n/a (service) | F128: 80 | G128: =IF(AND(ISNUMBER(E128),ISNUMBER(F128)),F128-E128,"") | H128: =IF(AND(ISNUMBER(G128),N(F128)>0),G128/F128,"") | J128: =IF(AND(ISNUMBER(E128),ISNUMBER(I128)),E128*I128,"") | L128: No | M128: No | N128: Hairdresser
A129: Hair Shampooing & Blowout Fee | B129: ba:itemname_hairshampooingfee | C129: Service | D129: n/a (service) | F129: 60 | G129: =IF(AND(ISNUMBER(E129),ISNUMBER(F129)),F129-E129,"") | H129: =IF(AND(ISNUMBER(G129),N(F129)>0),G129/F129,"") | J129: =IF(AND(ISNUMBER(E129),ISNUMBER(I129)),E129*I129,"") | L129: No | M129: No | N129: Hairdresser
A130: Hair Styling Fee | B130: ba:itemname_hairstylingfee | C130: Service | D130: n/a (service) | F130: 105 | G130: =IF(AND(ISNUMBER(E130),ISNUMBER(F130)),F130-E130,"") | H130: =IF(AND(ISNUMBER(G130),N(F130)>0),G130/F130,"") | J130: =IF(AND(ISNUMBER(E130),ISNUMBER(I130)),E130*I130,"") | L130: No | M130: No | N130: Hairdresser
A131: Lawyer Fee (Hourly) | B131: ba:itemname_hourlylawyerfee | C131: Service | D131: n/a (service) | F131: 225 | G131: =IF(AND(ISNUMBER(E131),ISNUMBER(F131)),F131-E131,"") | H131: =IF(AND(ISNUMBER(G131),N(F131)>0),G131/F131,"") | J131: =IF(AND(ISNUMBER(E131),ISNUMBER(I131)),E131*I131,"") | L131: No | M131: No | N131: Law Firm
A132: Nightclub Weekday Cover Charge | B132: ba:itemname_nightclubweekdaycovercharge | C132: Service | D132: n/a (service) | F132: 15 | G132: =IF(AND(ISNUMBER(E132),ISNUMBER(F132)),F132-E132,"") | H132: =IF(AND(ISNUMBER(G132),N(F132)>0),G132/F132,"") | J132: =IF(AND(ISNUMBER(E132),ISNUMBER(I132)),E132*I132,"") | L132: No | M132: No | N132: Nightclub
A133: Nightclub Weekend Cover Charge | B133: ba:itemname_nightclubweekendcovercharge | C133: Service | D133: n/a (service) | F133: 30 | G133: =IF(AND(ISNUMBER(E133),ISNUMBER(F133)),F133-E133,"") | H133: =IF(AND(ISNUMBER(G133),N(F133)>0),G133/F133,"") | J133: =IF(AND(ISNUMBER(E133),ISNUMBER(I133)),E133*I133,"") | L133: No | M133: No | N133: Nightclub
... A136: Travel Consultant Fee (Hourly) | B136: ba:itemname_hourlytravelconsultantfee | C136: Service | D136: n/a (service) | F136: 145 | G136: =IF(AND(ISNUMBER(E136),ISNUMBER(F136)),F136-E136,"") | H136: =IF(AND(ISNUMBER(G136),N(F136)>0),G136/F136,"") | J136: =IF(AND(ISNUMBER(E136),ISNUMBER(I136)),E136*I136,"") | L136: No | M136: No | N136: Travel Agency
...

Sheet Importers
A1: Importer | B1: Importer Type | C1: Item | D1: Availability | E1: Import Price ($/unit) | F1: Avg Selling Price ($/unit) | G1: Units per Box | H1: Can Go on Shortage?
A2: Aquatic Bay Cargo | B2: Raw Materials | C2: Barley | D2: Standard | E2: =IFERROR(INDEX(Items!$E$2:$E$138,MATCH(C2,Items!$A$2:$A$138,0)),"") -> 0.24 | F2: =IFERROR(INDEX(Items!$F$2:$F$138,MATCH(C2,Items!$A$2:$A$138,0)),"") | G2: =IFERROR(INDEX(Items!$I$2:$I$138,MATCH(C2,Items!$A$2:$A$138,0)),"") -> 500 | H2: No
A3: Aquatic Bay Cargo | B3: Raw Materials | C3: Blue Agave | D3: Standard | E3: =IFERROR(INDEX(Items!$E$2:$E$138,MATCH(C3,Items!$A$2:$A$138,0)),"") -> 0.12 | F3: =IFERROR(INDEX(Items!$F$2:$F$138,MATCH(C3,Items!$A$2:$A$138,0)),"") | G3: =IFERROR(INDEX(Items!$I$2:$I$138,MATCH(C3,Items!$A$2:$A$138,0)),"") -> 500 | H3: No
A4: Aquatic Bay Cargo | B4: Raw Materials | C4: Caffeine Extract | D4: Standard | E4: =IFERROR(INDEX(Items!$E$2:$E$138,MATCH(C4,Items!$A$2:$A$138,0)),"") -> 0.1 | F4: =IFERROR(INDEX(Items!$F$2:$F$138,MATCH(C4,Items!$A$2:$A$138,0)),"") | G4: =IFERROR(INDEX(Items!$I$2:$I$138,MATCH(C4,Items!$A$2:$A$138,0)),"") -> 500 | H4: No
A5: Aquatic Bay Cargo | B5: Raw Materials | C5: Carbon Dioxide | D5: Standard | E5: =IFERROR(INDEX(Items!$E$2:$E$138,MATCH(C5,Items!$A$2:$A$138,0)),"") -> 0.01 | F5: =IFERROR(INDEX(Items!$F$2:$F$138,MATCH(C5,Items!$A$2:$A$138,0)),"") | G5: =IFERROR(INDEX(Items!$I$2:$I$138,MATCH(C5,Items!$A$2:$A$138,0)),"") -> 500 | H5: No
A6: Aquatic Bay Cargo | B6: Raw Materials | C6: Cola Flavoring | D6: Standard | E6: =IFERROR(INDEX(Items!$E$2:$E$138,MATCH(C6,Items!$A$2:$A$138,0)),"") -> 0.02 | F6: =IFERROR(INDEX(Items!$F$2:$F$138,MATCH(C6,Items!$A$2:$A$138,0)),"") | G6: =IFERROR(INDEX(Items!$I$2:$I$138,MATCH(C6,Items!$A$2:$A$138,0)),"") -> 500 | H6: No
A7: Aquatic Bay Cargo | B7: Raw Materials | C7: Flavor Syrup | D7: Standard | E7: =IFERROR(INDEX(Items!$E$2:$E$138,MATCH(C7,Items!$A$2:$A$138,0)),"") -> 0.04 | F7: =IFERROR(INDEX(Items!$F$2:$F$138,MATCH(C7,Items!$A$2:$A$138,0)),"") | G7: =IFERROR(INDEX(Items!$I$2:$I$138,MATCH(C7,Items!$A$2:$A$138,0)),"") -> 500 | H7: No
A8: Aquatic Bay Cargo | B8: Raw Materials | C8: Grapes | D8: Standard | E8: =IFERROR(INDEX(Items!$E$2:$E$138,MATCH(C8,Items!$A$2:$A$138,0)),"") -> 0.35 | F8: =IFERROR(INDEX(Items!$F$2:$F$138,MATCH(C8,Items!$A$2:$A$138,0)),"") | G8: =IFERROR(INDEX(Items!$I$2:$I$138,MATCH(C8,Items!$A$2:$A$138,0)),"") -> 500 | H8: No
A9: Aquatic Bay Cargo | B9: Raw Materials | C9: Ground Coffee Beans | D9: Standard | E9: =IFERROR(INDEX(Items!$E$2:$E$138,MATCH(C9,Items!$A$2:$A$138,0)),"") -> 0.12 | F9: =IFERROR(INDEX(Items!$F$2:$F$138,MATCH(C9,Items!$A$2:$A$138,0)),"") | G9: =IFERROR(INDEX(Items!$I$2:$I$138,MATCH(C9,Items!$A$2:$A$138,0)),"") -> 500 | H9: No
A10: Aquatic Bay Cargo | B10: Raw Materials | C10: Hair Care Formula | D10: Standard | E10: =IFERROR(INDEX(Items!$E$2:$E$138,MATCH(C10,Items!$A$2:$A$138,0)),"") -> 2.5 | F10: =IFERROR(INDEX(Items!$F$2:$F$138,MATCH(C10,Items!$A$2:$A$138,0)),"") | G10: =IFERROR(INDEX(Items!$I$2:$I$138,MATCH(C10,Items!$A$2:$A$138,0)),"") -> 500 | H10: No
A11: Aquatic Bay Cargo | B11: Raw Materials | C11: Hops | D11: Standard | E11: =IFERROR(INDEX(Items!$E$2:$E$138,MATCH(C11,Items!$A$2:$A$138,0)),"") -> 0.02 | F11: =IFERROR(INDEX(Items!$F$2:$F$138,MATCH(C11,Items!$A$2:$A$138,0)),"") | G11: =IFERROR(INDEX(Items!$I$2:$I$138,MATCH(C11,Items!$A$2:$A$138,0)),"") -> 500 | H11: No
A12: Aquatic Bay Cargo | B12: Raw Materials | C12: Juniper Berries | D12: Standard | E12: =IFERROR(INDEX(Items!$E$2:$E$138,MATCH(C12,Items!$A$2:$A$138,0)),"") -> 0.15 | F12: =IFERROR(INDEX(Items!$F$2:$F$138,MATCH(C12,Items!$A$2:$A$138,0)),"") | G12: =IFERROR(INDEX(Items!$I$2:$I$138,MATCH(C12,Items!$A$2:$A$138,0)),"") -> 500 | H12: No
A13: Aquatic Bay Cargo | B13: Raw Materials | C13: Lime Juice | D13: Standard | E13: =IFERROR(INDEX(Items!$E$2:$E$138,MATCH(C13,Items!$A$2:$A$138,0)),"") -> 0.02 | F13: =IFERROR(INDEX(Items!$F$2:$F$138,MATCH(C13,Items!$A$2:$A$138,0)),"") | G13: =IFERROR(INDEX(Items!$I$2:$I$138,MATCH(C13,Items!$A$2:$A$138,0)),"") -> 500 | H13: No
... A134: United Ocean Import | B134: Finished Goods | C134: Whisky | D134: Standard | E134: =IFERROR(INDEX(Items!$E$2:$E$138,MATCH(C134,Items!$A$2:$A$138,0)),"") -> 8 | F134: =IFERROR(INDEX(Items!$F$2:$F$138,MATCH(C134,Items!$A$2:$A$138,0)),"") -> 26 | G134: =IFERROR(INDEX(Items!$I$2:$I$138,MATCH(C134,Items!$A$2:$A$138,0)),"") -> 300 | H134: Yes

Sheet Recipe Ingredients
A1: Output Item | B1: Ingredient | C1: Qty per Hour (per workstation) | D1: Ingredient Import Price ($/unit) | E1: Ingredient Cost per Hour ($) | F1: Qty per 1 Unit of Output
A2: Arty Fish Phone | B2: Resistors | C2: 300 | D2: =IFERROR(INDEX(Items!$E$2:$E$138,MATCH(B2,Items!$A$2:$A$138,0)),"") -> 4 | E2: =IF(ISNUMBER(D2),C2*D2,"") -> 1200 | F2: =C2/INDEX(Recipes!$C:$C,MATCH(A2,Recipes!$A:$A,0)) -> 10
A3: Arty Fish Phone | B3: Transistors | C3: 300 | D3: =IFERROR(INDEX(Items!$E$2:$E$138,MATCH(B3,Items!$A$2:$A$138,0)),"") -> 8 | E3: =IF(ISNUMBER(D3),C3*D3,"") -> 2400 | F3: =C3/INDEX(Recipes!$C:$C,MATCH(A3,Recipes!$A:$A,0)) -> 10
A4: Arty Fish Phone | B4: Capacitors | C4: 300 | D4: =IFERROR(INDEX(Items!$E$2:$E$138,MATCH(B4,Items!$A$2:$A$138,0)),"") -> 6 | E4: =IF(ISNUMBER(D4),C4*D4,"") -> 1800 | F4: =C4/INDEX(Recipes!$C:$C,MATCH(A4,Recipes!$A:$A,0)) -> 10
A5: Arty Fish Phone | B5: Integrated Circuits | C5: 60 | D5: =IFERROR(INDEX(Items!$E$2:$E$138,MATCH(B5,Items!$A$2:$A$138,0)),"") -> 10 | E5: =IF(ISNUMBER(D5),C5*D5,"") -> 600 | F5: =C5/INDEX(Recipes!$C:$C,MATCH(A5,Recipes!$A:$A,0)) -> 2
A6: Arty Fish Phone | B6: Copper Clad Laminate | C6: 30 | D6: =IFERROR(INDEX(Items!$E$2:$E$138,MATCH(B6,Items!$A$2:$A$138,0)),"") -> 8 | E6: =IF(ISNUMBER(D6),C6*D6,"") -> 240 | F6: =C6/INDEX(Recipes!$C:$C,MATCH(A6,Recipes!$A:$A,0)) -> 1
A7: Arty Fish Phone | B7: Speaker | C7: 30 | D7: =IFERROR(INDEX(Items!$E$2:$E$138,MATCH(B7,Items!$A$2:$A$138,0)),"") -> 6 | E7: =IF(ISNUMBER(D7),C7*D7,"") -> 180 | F7: =C7/INDEX(Recipes!$C:$C,MATCH(A7,Recipes!$A:$A,0)) -> 1
A8: Arty Fish Phone | B8: Microphone | C8: 30 | D8: =IFERROR(INDEX(Items!$E$2:$E$138,MATCH(B8,Items!$A$2:$A$138,0)),"") -> 8 | E8: =IF(ISNUMBER(D8),C8*D8,"") -> 240 | F8: =C8/INDEX(Recipes!$C:$C,MATCH(A8,Recipes!$A:$A,0)) -> 1
A9: Arty Fish Phone | B9: Plastic | C9: 30 | D9: =IFERROR(INDEX(Items!$E$2:$E$138,MATCH(B9,Items!$A$2:$A$138,0)),"") -> 0.6 | E9: =IF(ISNUMBER(D9),C9*D9,"") -> 18 | F9: =C9/INDEX(Recipes!$C:$C,MATCH(A9,Recipes!$A:$A,0)) -> 1
A10: Arty Fish Phone | B10: Glass | C10: 30 | D10: =IFERROR(INDEX(Items!$E$2:$E$138,MATCH(B10,Items!$A$2:$A$138,0)),"") -> 0.5 | E10: =IF(ISNUMBER(D10),C10*D10,"") -> 15 | F10: =C10/INDEX(Recipes!$C:$C,MATCH(A10,Recipes!$A:$A,0)) -> 1
A11: Arty Fish Phone | B11: Battery | C11: 30 | D11: =IFERROR(INDEX(Items!$E$2:$E$138,MATCH(B11,Items!$A$2:$A$138,0)),"") -> 16 | E11: =IF(ISNUMBER(D11),C11*D11,"") -> 480 | F11: =C11/INDEX(Recipes!$C:$C,MATCH(A11,Recipes!$A:$A,0)) -> 1
A12: Arty Fish Smartwatch | B12: Resistors | C12: 60 | D12: =IFERROR(INDEX(Items!$E$2:$E$138,MATCH(B12,Items!$A$2:$A$138,0)),"") -> 4 | E12: =IF(ISNUMBER(D12),C12*D12,"") -> 240 | F12: =C12/INDEX(Recipes!$C:$C,MATCH(A12,Recipes!$A:$A,0)) -> 2
A13: Arty Fish Smartwatch | B13: Transistors | C13: 60 | D13: =IFERROR(INDEX(Items!$E$2:$E$138,MATCH(B13,Items!$A$2:$A$138,0)),"") -> 8 | E13: =IF(ISNUMBER(D13),C13*D13,"") -> 480 | F13: =C13/INDEX(Recipes!$C:$C,MATCH(A13,Recipes!$A:$A,0)) -> 2
... A185: ZanaMan Smartwatch | B185: Battery | C185: 30 | D185: =IFERROR(INDEX(Items!$E$2:$E$138,MATCH(B185,Items!$A$2:$A$138,0)),"") -> 16 | E185: =IF(ISNUMBER(D185),C185*D185,"") -> 480 | F185: =C185/INDEX(Recipes!$C:$C,MATCH(A185,Recipes!$A:$A,0)) -> 1

Sheet Recipes
A1: Output Item | B1: Ingredients (qty per hour) | C1: Output / Hour (skill 100) | D1: Output / Hour (skill 0) | E1: Machines Used | F1: Ingredient Cost per Hour ($) | G1: Ingredient Cost per Unit ($, skill 100) | H1: Import Price of Output ($/unit) | I1: Avg Selling Price ($/unit) | J1: Profit per Unit if Sold ($) | K1: Saving vs Importing ($/unit) | L1: Gross Profit per Hour per Workstation ($)
A2: Arty Fish Phone | B2: 300 Resistors + 300 Transistors + 300 Capacitors + 60 Integrated Circuits + 30 Copper Clad Laminate + 30 Speaker + 30 Microphone + 30 Plastic + 30 Glass + 30 Battery | C2: 30 | D2: =ROUND(C2*0.5,0) -> 15 | E2: Kiln Machine, Laser Cutting Machine, Consumer Goods Assembly Machine | F2: =SUMIFS('Recipe Ingredients'!$E$2:$E$185,'Recipe Ingredients'!$A$2:$A$185,A2) -> 7173 | G2: =IF(C2>0,F2/C2,"") -> 239.1 | H2: =IFERROR(INDEX(Items!$E$2:$E$138,MATCH(A2,Items!$A$2:$A$138,0)),"") -> 350 | I2: =IFERROR(INDEX(Items!$F$2:$F$138,MATCH(A2,Items!$A$2:$A$138,0)),"") -> 799 | J2: =IF(ISNUMBER(I2),I2-G2,"") -> 559.9 | K2: =IF(ISNUMBER(H2),H2-G2,"") -> 110.9 | L2: =IF(ISNUMBER(J2),J2*C2,"") -> 16797
A3: Arty Fish Smartwatch | B3: 60 Resistors + 60 Transistors + 60 Capacitors + 30 Integrated Circuits + 30 Copper Clad Laminate + 30 Speaker + 30 Microphone + 5 Plastic + 5 Glass + 30 Battery | C3: 30 | D3: =ROUND(C3*0.5,0) -> 15 | E3: Kiln Machine, Laser Cutting Machine, Consumer Goods Assembly Machine | F3: =SUMIFS('Recipe Ingredients'!$E$2:$E$185,'Recipe Ingredients'!$A$2:$A$185,A3) -> 2525.5 | G3: =IF(C3>0,F3/C3,"") -> 84.183333 | H3: =IFERROR(INDEX(Items!$E$2:$E$138,MATCH(A3,Items!$A$2:$A$138,0)),"") -> 150 | I3: =IFERROR(INDEX(Items!$F$2:$F$138,MATCH(A3,Items!$A$2:$A$138,0)),"") -> 324 | J3: =IF(ISNUMBER(I3),I3-G3,"") -> 239.81667 | K3: =IF(ISNUMBER(H3),H3-G3,"") -> 65.816667 | L3: =IF(ISNUMBER(J3),J3*C3,"") -> 7194.5
A4: Bag of Apples | B4: 50 Seeds (Apple) + 50 Water | C4: 250 | D4: =ROUND(C4*0.5,0) -> 125 | E4: Hydroponic Planter, Food Assembly Machine | F4: =SUMIFS('Recipe Ingredients'!$E$2:$E$185,'Recipe Ingredients'!$A$2:$A$185,A4) -> 25.5 | G4: =IF(C4>0,F4/C4,"") -> 0.102 | H4: =IFERROR(INDEX(Items!$E$2:$E$138,MATCH(A4,Items!$A$2:$A$138,0)),"") -> 0.32 | I4: =IFERROR(INDEX(Items!$F$2:$F$138,MATCH(A4,Items!$A$2:$A$138,0)),"") -> 2.89 | J4: =IF(ISNUMBER(I4),I4-G4,"") -> 2.788 | K4: =IF(ISNUMBER(H4),H4-G4,"") -> 0.218 | L4: =IF(ISNUMBER(J4),J4*C4,"") -> 697
A5: Bag of Bananas | B5: 50 Seeds (Banana) + 50 Water | C5: 250 | D5: =ROUND(C5*0.5,0) -> 125 | E5: Hydroponic Planter, Food Assembly Machine | F5: =SUMIFS('Recipe Ingredients'!$E$2:$E$185,'Recipe Ingredients'!$A$2:$A$185,A5) -> 25.5 | G5: =IF(C5>0,F5/C5,"") -> 0.102 | H5: =IFERROR(INDEX(Items!$E$2:$E$138,MATCH(A5,Items!$A$2:$A$138,0)),"") -> 0.26 | I5: =IFERROR(INDEX(Items!$F$2:$F$138,MATCH(A5,Items!$A$2:$A$138,0)),"") -> 2.35 | J5: =IF(ISNUMBER(I5),I5-G5,"") -> 2.248 | K5: =IF(ISNUMBER(H5),H5-G5,"") -> 0.158 | L5: =IF(ISNUMBER(J5),J5*C5,"") -> 562
A6: Bag of Carrots | B6: 50 Seeds (Carrot) + 50 Water | C6: 250 | D6: =ROUND(C6*0.5,0) -> 125 | E6: Hydroponic Planter, Food Assembly Machine | F6: =SUMIFS('Recipe Ingredients'!$E$2:$E$185,'Recipe Ingredients'!$A$2:$A$185,A6) -> 25.5 | G6: =IF(C6>0,F6/C6,"") -> 0.102 | H6: =IFERROR(INDEX(Items!$E$2:$E$138,MATCH(A6,Items!$A$2:$A$138,0)),"") -> 0.28 | I6: =IFERROR(INDEX(Items!$F$2:$F$138,MATCH(A6,Items!$A$2:$A$138,0)),"") -> 2.24 | J6: =IF(ISNUMBER(I6),I6-G6,"") -> 2.138 | K6: =IF(ISNUMBER(H6),H6-G6,"") -> 0.178 | L6: =IF(ISNUMBER(J6),J6*C6,"") -> 534.5
A7: Bag of Lettuce | B7: 50 Seeds (Lettuce) + 50 Water | C7: 250 | D7: =ROUND(C7*0.5,0) -> 125 | E7: Hydroponic Planter, Food Assembly Machine | F7: =SUMIFS('Recipe Ingredients'!$E$2:$E$185,'Recipe Ingredients'!$A$2:$A$185,A7) -> 25.5 | G7: =IF(C7>0,F7/C7,"") -> 0.102 | H7: =IFERROR(INDEX(Items!$E$2:$E$138,MATCH(A7,Items!$A$2:$A$138,0)),"") -> 0.28 | I7: =IFERROR(INDEX(Items!$F$2:$F$138,MATCH(A7,Items!$A$2:$A$138,0)),"") -> 2.12 | J7: =IF(ISNUMBER(I7),I7-G7,"") -> 2.018 | K7: =IF(ISNUMBER(H7),H7-G7,"") -> 0.178 | L7: =IF(ISNUMBER(J7),J7*C7,"") -> 504.5
A8: Bag of Pears | B8: 50 Seeds (Pear) + 50 Water | C8: 250 | D8: =ROUND(C8*0.5,0) -> 125 | E8: Hydroponic Planter, Food Assembly Machine | F8: =SUMIFS('Recipe Ingredients'!$E$2:$E$185,'Recipe Ingredients'!$A$2:$A$185,A8) -> 25.5 | G8: =IF(C8>0,F8/C8,"") -> 0.102 | H8: =IFERROR(INDEX(Items!$E$2:$E$138,MATCH(A8,Items!$A$2:$A$138,0)),"") -> 0.29 | I8: =IFERROR(INDEX(Items!$F$2:$F$138,MATCH(A8,Items!$A$2:$A$138,0)),"") -> 2.62 | J8: =IF(ISNUMBER(I8),I8-G8,"") -> 2.518 | K8: =IF(ISNUMBER(H8),H8-G8,"") -> 0.188 | L8: =IF(ISNUMBER(J8),J8*C8,"") -> 629.5
A9: Bag of Tomatoes | B9: 50 Seeds (Tomato) + 50 Water | C9: 250 | D9: =ROUND(C9*0.5,0) -> 125 | E9: Hydroponic Planter, Food Assembly Machine | F9: =SUMIFS('Recipe Ingredients'!$E$2:$E$185,'Recipe Ingredients'!$A$2:$A$185,A9) -> 25.5 | G9: =IF(C9>0,F9/C9,"") -> 0.102 | H9: =IFERROR(INDEX(Items!$E$2:$E$138,MATCH(A9,Items!$A$2:$A$138,0)),"") -> 0.29 | I9: =IFERROR(INDEX(Items!$F$2:$F$138,MATCH(A9,Items!$A$2:$A$138,0)),"") -> 2.56 | J9: =IF(ISNUMBER(I9),I9-G9,"") -> 2.458 | K9: =IF(ISNUMBER(H9),H9-G9,"") -> 0.188 | L9: =IF(ISNUMBER(J9),J9*C9,"") -> 614.5
A10: Beer | B10: 50 Water + 50 Barley + 50 Yeast + 50 Carbon Dioxide + 50 Hops | C10: 50 | D10: =ROUND(C10*0.5,0) -> 25 | E10: Industrial Blending Machine, Bottling Machine, Food Assembly Machine | F10: =SUMIFS('Recipe Ingredients'!$E$2:$E$185,'Recipe Ingredients'!$A$2:$A$185,A10) -> 14.5 | G10: =IF(C10>0,F10/C10,"") -> 0.29 | H10: =IFERROR(INDEX(Items!$E$2:$E$138,MATCH(A10,Items!$A$2:$A$138,0)),"") -> 2 | I10: =IFERROR(INDEX(Items!$F$2:$F$138,MATCH(A10,Items!$A$2:$A$138,0)),"") -> 12 | J10: =IF(ISNUMBER(I10),I10-G10,"") -> 11.71 | K10: =IF(ISNUMBER(H10),H10-G10,"") -> 1.71 | L10: =IF(ISNUMBER(J10),J10*C10,"") -> 585.5
A11: Bottle of Wine | B11: 100 Grapes + 50 Sugar + 50 Yeast | C11: 50 | D11: =ROUND(C11*0.5,0) -> 25 | E11: Industrial Blending Machine, Bottling Machine, Food Assembly Machine | F11: =SUMIFS('Recipe Ingredients'!$E$2:$E$185,'Recipe Ingredients'!$A$2:$A$185,A11) -> 38 | G11: =IF(C11>0,F11/C11,"") -> 0.76 | H11: =IFERROR(INDEX(Items!$E$2:$E$138,MATCH(A11,Items!$A$2:$A$138,0)),"") -> 5.8 | I11: =IFERROR(INDEX(Items!$F$2:$F$138,MATCH(A11,Items!$A$2:$A$138,0)),"") -> 21 | J11: =IF(ISNUMBER(I11),I11-G11,"") -> 20.24 | K11: =IF(ISNUMBER(H11),H11-G11,"") -> 5.04 | L11: =IF(ISNUMBER(J11),J11*C11,"") -> 1012
A12: Burger | B12: 200 Ground Beef + 200 Dough + 40 Cheese | C12: 200 | D12: =ROUND(C12*0.5,0) -> 100 | E12: Industrial Blending Machine, Automated Baking Machine, Food Assembly Machine | F12: =SUMIFS('Recipe Ingredients'!$E$2:$E$185,'Recipe Ingredients'!$A$2:$A$185,A12) -> 232.8 | G12: =IF(C12>0,F12/C12,"") -> 1.164 | H12: =IFERROR(INDEX(Items!$E$2:$E$138,MATCH(A12,Items!$A$2:$A$138,0)),"") -> 4.75 | I12: =IFERROR(INDEX(Items!$F$2:$F$138,MATCH(A12,Items!$A$2:$A$138,0)),"") -> 12.5 | J12: =IF(ISNUMBER(I12),I12-G12,"") -> 11.336 | K12: =IF(ISNUMBER(H12),H12-G12,"") -> 3.586 | L12: =IF(ISNUMBER(J12),J12*C12,"") -> 2267.2
A13: Cheese Platter | B13: 200 Cheese | C13: 200 | D13: =ROUND(C13*0.5,0) -> 100 | E13: Industrial Blending Machine, Automated Baking Machine, Food Assembly Machine | F13: =SUMIFS('Recipe Ingredients'!$E$2:$E$185,'Recipe Ingredients'!$A$2:$A$185,A13) -> 64 | G13: =IF(C13>0,F13/C13,"") -> 0.32 | H13: =IFERROR(INDEX(Items!$E$2:$E$138,MATCH(A13,Items!$A$2:$A$138,0)),"") -> 1 | I13: =IFERROR(INDEX(Items!$F$2:$F$138,MATCH(A13,Items!$A$2:$A$138,0)),"") -> 15 | J13: =IF(ISNUMBER(I13),I13-G13,"") -> 14.68 | K13: =IF(ISNUMBER(H13),H13-G13,"") -> 0.68 | L13: =IF(ISNUMBER(J13),J13*C13,"") -> 2936
... A63: ZanaMan Smartwatch | B63: 60 Resistors + 60 Transistors + 60 Capacitors + 30 Integrated Circuits + 30 Copper Clad Laminate + 30 Speaker + 30 Microphone + 5 Plastic + 5 Glass + 30 Battery | C63: 30 | D63: =ROUND(C63*0.5,0) -> 15 | E63: Kiln Machine, Laser Cutting Machine, Consumer Goods Assembly Machine | F63: =SUMIFS('Recipe Ingredients'!$E$2:$E$185,'Recipe Ingredients'!$A$2:$A$185,A63) -> 2525.5 | G63: =IF(C63>0,F63/C63,"") -> 84.183333 | H63: =IFERROR(INDEX(Items!$E$2:$E$138,MATCH(A63,Items!$A$2:$A$138,0)),"") -> 250 | I63: =IFERROR(INDEX(Items!$F$2:$F$138,MATCH(A63,Items!$A$2:$A$138,0)),"") -> 399 | J63: =IF(ISNUMBER(I63),I63-G63,"") -> 314.81667 | K63: =IF(ISNUMBER(H63),H63-G63,"") -> 165.81667 | L63: =IF(ISNUMBER(J63),J63*C63,"") -> 9444.5

Sheet Business Types
A1: Business Type | B1: Product | C1: Demand Impact | D1: Avg Selling Price ($/unit) | E1: Import Price ($/unit) | F1: Product Sources
A2: Bookstore | B2: Novel | C2: 1 | D2: =IFERROR(INDEX(Items!$F$2:$F$138,MATCH(B2,Items!$A$2:$A$138,0)),"") -> 28 | E2: =IFERROR(INDEX(Items!$E$2:$E$138,MATCH(B2,Items!$A$2:$A$138,0)),"") -> 11.5 | F2: Importer
A3: Bookstore | B3: Youth Novel | C3: 1 | D3: =IFERROR(INDEX(Items!$F$2:$F$138,MATCH(B3,Items!$A$2:$A$138,0)),"") -> 14 | E3: =IFERROR(INDEX(Items!$E$2:$E$138,MATCH(B3,Items!$A$2:$A$138,0)),"") -> 5.5 | F3: Importer
A4: Bookstore | B4: Motivational Book | C4: 1 | D4: =IFERROR(INDEX(Items!$F$2:$F$138,MATCH(B4,Items!$A$2:$A$138,0)),"") -> 25 | E4: =IFERROR(INDEX(Items!$E$2:$E$138,MATCH(B4,Items!$A$2:$A$138,0)),"") -> 10 | F4: Importer
A5: Bookstore | B5: Technical Manual | C5: 1 | D5: =IFERROR(INDEX(Items!$F$2:$F$138,MATCH(B5,Items!$A$2:$A$138,0)),"") -> 44 | E5: =IFERROR(INDEX(Items!$E$2:$E$138,MATCH(B5,Items!$A$2:$A$138,0)),"") -> 18 | F5: Importer
A6: Bookstore | B6: Picture Book | C6: 1 | D6: =IFERROR(INDEX(Items!$F$2:$F$138,MATCH(B6,Items!$A$2:$A$138,0)),"") -> 6 | E6: =IFERROR(INDEX(Items!$E$2:$E$138,MATCH(B6,Items!$A$2:$A$138,0)),"") -> 2.5 | F6: Importer
A7: Bookstore | B7: Limited Edition Book | C7: 1 | D7: =IFERROR(INDEX(Items!$F$2:$F$138,MATCH(B7,Items!$A$2:$A$138,0)),"") -> 90 | E7: =IFERROR(INDEX(Items!$E$2:$E$138,MATCH(B7,Items!$A$2:$A$138,0)),"") -> 45 | F7: Importer
A8: Bookstore | B8: Gift (Cheap) | C8: 0.25 | D8: =IFERROR(INDEX(Items!$F$2:$F$138,MATCH(B8,Items!$A$2:$A$138,0)),"") -> 18 | E8: =IFERROR(INDEX(Items!$E$2:$E$138,MATCH(B8,Items!$A$2:$A$138,0)),"") -> 5 | F8: Importer
A9: Bookstore | B9: Flower (Cheap) | C9: 0.25 | D9: =IFERROR(INDEX(Items!$F$2:$F$138,MATCH(B9,Items!$A$2:$A$138,0)),"") -> 25 | E9: =IFERROR(INDEX(Items!$E$2:$E$138,MATCH(B9,Items!$A$2:$A$138,0)),"") -> 6 | F9: Importer
A10: Bookstore | B10: Noize Boss Earbuds | C10: 0.33 | D10: =IFERROR(INDEX(Items!$F$2:$F$138,MATCH(B10,Items!$A$2:$A$138,0)),"") -> 159 | E10: =IFERROR(INDEX(Items!$E$2:$E$138,MATCH(B10,Items!$A$2:$A$138,0)),"") -> 79 | F10: Importer
A11: Bookstore | B11: Umbrella | C11: 0.75 | D11: =IFERROR(INDEX(Items!$F$2:$F$138,MATCH(B11,Items!$A$2:$A$138,0)),"") -> 24 | E11: =IFERROR(INDEX(Items!$E$2:$E$138,MATCH(B11,Items!$A$2:$A$138,0)),"") -> 7 | F11: Importer
A12: Cinema | B12: Cinema Ticket | C12: 1 | D12: =IFERROR(INDEX(Items!$F$2:$F$138,MATCH(B12,Items!$A$2:$A$138,0)),"") -> 16 | E12: =IFERROR(INDEX(Items!$E$2:$E$138,MATCH(B12,Items!$A$2:$A$138,0)),"") | F12: Wholesaler
A13: Cinema | B13: Soda Can | C13: 1 | D13: =IFERROR(INDEX(Items!$F$2:$F$138,MATCH(B13,Items!$A$2:$A$138,0)),"") -> 3 | E13: =IFERROR(INDEX(Items!$E$2:$E$138,MATCH(B13,Items!$A$2:$A$138,0)),"") -> 0.5 | F13: Wholesaler
... A44: Electronics Store | B44: Energy Drink | C44: 0.75 | D44: =IFERROR(INDEX(Items!$F$2:$F$138,MATCH(B44,Items!$A$2:$A$138,0)),"") -> 3.9 | E44: =IFERROR(INDEX(Items!$E$2:$E$138,MATCH(B44,Items!$A$2:$A$138,0)),"") -> 0.9 | F44: Importer, Factory
A45: Event Planning Agency | B45: Event Planning Fee (Hourly) | C45: 1 | D45: =IFERROR(INDEX(Items!$F$2:$F$138,MATCH(B45,Items!$A$2:$A$138,0)),"") -> 150 | E45: =IFERROR(INDEX(Items!$E$2:$E$138,MATCH(B45,Items!$A$2:$A$138,0)),"")
A46: Fast Food Restaurant | B46: Burger | C46: 1 | D46: =IFERROR(INDEX(Items!$F$2:$F$138,MATCH(B46,Items!$A$2:$A$138,0)),"") -> 12.5 | E46: =IFERROR(INDEX(Items!$E$2:$E$138,MATCH(B46,Items!$A$2:$A$138,0)),"") -> 4.75 | F46: Wholesaler
A47: Fast Food Restaurant | B47: French Fries | C47: 1 | D47: =IFERROR(INDEX(Items!$F$2:$F$138,MATCH(B47,Items!$A$2:$A$138,0)),"") -> 6.25 | E47: =IFERROR(INDEX(Items!$E$2:$E$138,MATCH(B47,Items!$A$2:$A$138,0)),"") -> 2.22 | F47: Wholesaler
A48: Fast Food Restaurant | B48: Hotdog | C48: 1 | D48: =IFERROR(INDEX(Items!$F$2:$F$138,MATCH(B48,Items!$A$2:$A$138,0)),"") -> 11.65 | E48: =IFERROR(INDEX(Items!$E$2:$E$138,MATCH(B48,Items!$A$2:$A$138,0)),"") -> 4.45 | F48: Wholesaler
A49: Fast Food Restaurant | B49: Pizza | C49: 1 | D49: =IFERROR(INDEX(Items!$F$2:$F$138,MATCH(B49,Items!$A$2:$A$138,0)),"") -> 22 | E49: =IFERROR(INDEX(Items!$E$2:$E$138,MATCH(B49,Items!$A$2:$A$138,0)),"") -> 8 | F49: Wholesaler
A50: Fast Food Restaurant | B50: Salad | C50: 1 | D50: =IFERROR(INDEX(Items!$F$2:$F$138,MATCH(B50,Items!$A$2:$A$138,0)),"") -> 13 | E50: =IFERROR(INDEX(Items!$E$2:$E$138,MATCH(B50,Items!$A$2:$A$138,0)),"") -> 4.9 | F50: Wholesaler
A51: Fast Food Restaurant | B51: Soda Can | C51: 1 | D51: =IFERROR(INDEX(Items!$F$2:$F$138,MATCH(B51,Items!$A$2:$A$138,0)),"") -> 3 | E51: =IFERROR(INDEX(Items!$E$2:$E$138,MATCH(B51,Items!$A$2:$A$138,0)),"") -> 0.5 | F51: Wholesaler
A52: Fast Food Restaurant | B52: Ice Cream | C52: 1 | D52: =IFERROR(INDEX(Items!$F$2:$F$138,MATCH(B52,Items!$A$2:$A$138,0)),"") -> 11.5 | E52: =IFERROR(INDEX(Items!$E$2:$E$138,MATCH(B52,Items!$A$2:$A$138,0)),"") -> 4.33 | F52: Wholesaler
A53: Fast Food Restaurant | B53: Bag of Apples | C53: 0.7 | D53: =IFERROR(INDEX(Items!$F$2:$F$138,MATCH(B53,Items!$A$2:$A$138,0)),"") -> 2.89 | E53: =IFERROR(INDEX(Items!$E$2:$E$138,MATCH(B53,Items!$A$2:$A$138,0)),"") -> 0.32 | F53: Wholesaler
A54: Fast Food Restaurant | B54: Bag of Bananas | C54: 0.4 | D54: =IFERROR(INDEX(Items!$F$2:$F$138,MATCH(B54,Items!$A$2:$A$138,0)),"") -> 2.35 | E54: =IFERROR(INDEX(Items!$E$2:$E$138,MATCH(B54,Items!$A$2:$A$138,0)),"") -> 0.26 | F54: Wholesaler
A55: Fast Food Restaurant | B55: Chicken Kabob Skewer | C55: 1 | D55: =IFERROR(INDEX(Items!$F$2:$F$138,MATCH(B55,Items!$A$2:$A$138,0)),"") -> 14 | E55: =IFERROR(INDEX(Items!$E$2:$E$138,MATCH(B55,Items!$A$2:$A$138,0)),"") -> 5.2 | F55: Wholesaler
A56: Florist | B56: Flower (Cheap) | C56: 1 | D56: =IFERROR(INDEX(Items!$F$2:$F$138,MATCH(B56,Items!$A$2:$A$138,0)),"") -> 25 | E56: =IFERROR(INDEX(Items!$E$2:$E$138,MATCH(B56,Items!$A$2:$A$138,0)),"") -> 6 | F56: Wholesaler
A57: Florist | B57: Flower (Expensive) | C57: 1 | D57: =IFERROR(INDEX(Items!$F$2:$F$138,MATCH(B57,Items!$A$2:$A$138,0)),"") -> 40 | E57: =IFERROR(INDEX(Items!$E$2:$E$138,MATCH(B57,Items!$A$2:$A$138,0)),"") -> 10 | F57: Wholesaler
... A80: Gift Shop | B80: Noize Boss Earbuds | C80: 0.2 | D80: =IFERROR(INDEX(Items!$F$2:$F$138,MATCH(B80,Items!$A$2:$A$138,0)),"") -> 159 | E80: =IFERROR(INDEX(Items!$E$2:$E$138,MATCH(B80,Items!$A$2:$A$138,0)),"") -> 79 | F80: Wholesaler, Importer
A81: Graphic Designer | B81: Graphic Designer Fee (Hourly) | C81: 1 | D81: =IFERROR(INDEX(Items!$F$2:$F$138,MATCH(B81,Items!$A$2:$A$138,0)),"") -> 160 | E81: =IFERROR(INDEX(Items!$E$2:$E$138,MATCH(B81,Items!$A$2:$A$138,0)),"")
A82: Gym | B82: Gym Cover Charge | C82: 1 | D82: =IFERROR(INDEX(Items!$F$2:$F$138,MATCH(B82,Items!$A$2:$A$138,0)),"") -> 20 | E82: =IFERROR(INDEX(Items!$E$2:$E$138,MATCH(B82,Items!$A$2:$A$138,0)),"") | F82: Wholesaler
A83: Gym | B83: Energy Drink | C83: 1 | D83: =IFERROR(INDEX(Items!$F$2:$F$138,MATCH(B83,Items!$A$2:$A$138,0)),"") -> 3.9 | E83: =IFERROR(INDEX(Items!$E$2:$E$138,MATCH(B83,Items!$A$2:$A$138,0)),"") -> 0.9 | F83: Wholesaler
A84: Gym | B84: Soda Can | C84: 1 | D84: =IFERROR(INDEX(Items!$F$2:$F$138,MATCH(B84,Items!$A$2:$A$138,0)),"") -> 3 | E84: =IFERROR(INDEX(Items!$E$2:$E$138,MATCH(B84,Items!$A$2:$A$138,0)),"") -> 0.5 | F84: Wholesaler
A85: Hairdresser | B85: Hair Shampooing & Blowout Fee | C85: 1 | D85: =IFERROR(INDEX(Items!$F$2:$F$138,MATCH(B85,Items!$A$2:$A$138,0)),"") -> 60 | E85: =IFERROR(INDEX(Items!$E$2:$E$138,MATCH(B85,Items!$A$2:$A$138,0)),"") | F85: Wholesaler
A86: Hairdresser | B86: Hair Chemical / Color Fee | C86: 1 | D86: =IFERROR(INDEX(Items!$F$2:$F$138,MATCH(B86,Items!$A$2:$A$138,0)),"") -> 150 | E86: =IFERROR(INDEX(Items!$E$2:$E$138,MATCH(B86,Items!$A$2:$A$138,0)),"") | F86: Wholesaler
A87: Hairdresser | B87: Hair Cutting Fee | C87: 1 | D87: =IFERROR(INDEX(Items!$F$2:$F$138,MATCH(B87,Items!$A$2:$A$138,0)),"") -> 80 | E87: =IFERROR(INDEX(Items!$E$2:$E$138,MATCH(B87,Items!$A$2:$A$138,0)),"") | F87: Wholesaler
A88: Hairdresser | B88: Hair Styling Fee | C88: 1 | D88: =IFERROR(INDEX(Items!$F$2:$F$138,MATCH(B88,Items!$A$2:$A$138,0)),"") -> 105 | E88: =IFERROR(INDEX(Items!$E$2:$E$138,MATCH(B88,Items!$A$2:$A$138,0)),"") | F88: Wholesaler
A89: Hairdresser | B89: Hair Care Product | C89: 1 | D89: =IFERROR(INDEX(Items!$F$2:$F$138,MATCH(B89,Items!$A$2:$A$138,0)),"") -> 19 | E89: =IFERROR(INDEX(Items!$E$2:$E$138,MATCH(B89,Items!$A$2:$A$138,0)),"") -> 9 | F89: Wholesaler
A90: Jewelry Store | B90: Jewelry (Cheap) | C90: 1 | D90: =IFERROR(INDEX(Items!$F$2:$F$138,MATCH(B90,Items!$A$2:$A$138,0)),"") -> 160 | E90: =IFERROR(INDEX(Items!$E$2:$E$138,MATCH(B90,Items!$A$2:$A$138,0)),"") -> 91 | F90: Importer, Factory
A91: Jewelry Store | B91: Jewelry (Expensive) | C91: 1 | D91: =IFERROR(INDEX(Items!$F$2:$F$138,MATCH(B91,Items!$A$2:$A$138,0)),"") -> 1270 | E91: =IFERROR(INDEX(Items!$E$2:$E$138,MATCH(B91,Items!$A$2:$A$138,0)),"") -> 768 | F91: Importer, Factory
A92: Jewelry Store | B92: ZanaMan Smartwatch | C92: 0.5 | D92: =IFERROR(INDEX(Items!$F$2:$F$138,MATCH(B92,Items!$A$2:$A$138,0)),"") -> 399 | E92: =IFERROR(INDEX(Items!$E$2:$E$138,MATCH(B92,Items!$A$2:$A$138,0)),"") -> 250 | F92: Importer, Factory
...

Sheet Furniture & Equipment
A1: Item | B1: Item ID (game) | C1: Function | D1: Purchase Price ($) | E1: Added Customers / Hour | F1: Storage Capacity (boxes)
A2: Acoustic Panel 01 | B2: ba:itemname_acousticpanel01 | C2: Decoration | D2: 120
A3: Acoustic Panel 02 | B3: ba:itemname_acousticpanel02 | C3: Decoration | D3: 20
A4: Acoustic Panel 03 | B4: ba:itemname_acousticpanel03 | C4: Decoration | D4: 20
A5: Agave (Big) | B5: ba:itemname_agavebig | C5: Decoration | D5: 140
A6: Agave (Small) | B6: ba:itemname_agavesmall | C6: Decoration | D6: 90
A7: Air Conditioner | B7: ba:itemname_wallairconditionerinterior | C7: Decoration | D7: 575
A8: Arm Chair Luxury | B8: ba:itemname_armchairluxury | C8: Seat | D8: 310
A9: Automated Baking Machine | B9: ba:itemname_automatedbakingmachine | C9: Factory Machine | D9: 75000
A10: Backstage Sign | B10: ba:itemname_backstagesign | C10: Decoration | D10: 250
A11: Bakery Showcase | B11: ba:itemname_bakeryshowcase | C11: Showcase Shelf | D11: 895 | E11: 20
A12: Barbeque Grill | B12: ba:itemname_barbequegrill | C12: Decoration | D12: 420
A13: Barstool | B13: ba:itemname_barstool | C13: Seat | D13: 120
A14: Basic Gaming PC Setup | B14: ba:itemname_gamingcomputer | C14: Workstation, Computer | D14: 1500 | E14: 1
A15: Basic Shelf (Wall Mounted) | B15: ba:itemname_wallmountedbasicshelf | C15: Decoration | D15: 25
A16: Bathroom Mirror | B16: ba:itemname_mirrorwallmounted | C16: Decoration | D16: 180
A17: Bathroom Shelf | B17: ba:itemname_towelwall | C17: Decoration | D17: 70
A18: Bathroom Sign | B18: ba:itemname_bathroomsignwallmounted | C18: Decoration | D18: 45
A19: Bathroom Stall | B19: ba:itemname_toiletstall | C19: Activity, Toilet | D19: 2100
A20: Bathtub | B20: ba:itemname_bathtub | C20: Activity | D20: 650
A21: Beach Towel (Extended) | B21: ba:itemname_beachtowelextended | C21: Seat | D21: 20
A22: Beach Towel (Folded) | B22: ba:itemname_beachtowelfolded | C22: Decoration | D22: 20
A23: Bed (Double Iron Canopy) | B23: ba:itemname_beddoubleironcanopy | C23: Activity | D23: 2450
A24: Bed (Double Iron) | B24: ba:itemname_beddoubleiron | C24: Activity | D24: 1850
A25: Bed (Double Modern Canopy) | B25: ba:itemname_beddoublemoderncanopy | C25: Activity | D25: 1725
A26: Bed (Double Wooden) | B26: ba:itemname_beddoublewooden | C26: Activity | D26: 1500
... A41: Books With Bookends | B41: ba:itemname_bookswithbookends | C41: Decoration | D41: 97
A42: Bookshelf (Large Decorative) | B42: ba:itemname_largedecorativebookshelf | C42: Activity | D42: 780 | F42: 21
A43: Bookshelf (Large) | B43: ba:itemname_largebookshelf | C43: Showcase Shelf | D43: 780 | E43: 50
A44: Bookshelf (Small Decorative) | B44: ba:itemname_decorativebookshelf | C44: Activity | D44: 350 | F44: 7
A45: Bookshelf (Small) | B45: ba:itemname_singlebookshelf | C45: Showcase Shelf | D45: 350 | E45: 20
A46: Bottling Machine | B46: ba:itemname_bottlingmachine | C46: Factory Machine | D46: 27500
A47: Boxing Bag | B47: ba:itemname_boxingbag | C47: Activity, Workout Machine | D47: 450 | E47: 2
A48: Bush (Modular Rectangular Curve) | B48: ba:itemname_bushmodularrectangularcurve | C48: Decoration | D48: 140
A49: Bush (Modular Rectangular Straight) | B49: ba:itemname_bushmodularrectangularstraight | C49: Decoration | D49: 140
A50: Bush (Round) | B50: ba:itemname_bushround | C50: Decoration | D50: 160
A51: Cabinet Corner | B51: ba:itemname_countercorner | C51: Work Surface | D51: 470
A52: Cabinet End (Left) | B52: ba:itemname_counterleftend | C52: Work Surface | D52: 470
A53: Cabinet End (Right) | B53: ba:itemname_counterrightend | C53: Work Surface | D53: 470
A54: Cabinet with Doors | B54: ba:itemname_counter2 | C54: Work Surface | D54: 470
...

Sheet Read Me
A1: Big Ambitions - Items, Importers & Prices
A3: Source | B3: Extracted directly from the installed game files (Addressables bundles in Big Ambitions_Data/StreamingAssets/aa, decompiled game code for the pricing rules, English names from locale/en.json). Pulled 2026-09-27.
A5: Sheets
A6: Items | B6: Every product in the game (137): 59 raw materials, 61 finished goods, 15 services, plus supplies. Import price, average selling price, margin, box size, weekly order cap, and which businesses sell it.
A7: Importers | B7: All 8 importers and every item each one sells (4 raw-material importers, 4 finished-goods importers).
A8: Recipes | B8: All 62 factory recipes: output per hour, machines, ingredient cost per unit, profit per unit, and saving vs buying the finished good from an importer.
A9: Recipe Ingredients | B9: One row per recipe ingredient (long format) - the easiest sheet to build a bill-of-materials / production calculator from.
A10: Business Types | B10: Which products each business type sells and how much each contributes to demand.
A11: Furniture & Equipment | B11: Purchase price of every buyable furniture / machine / shelf (530 items), incl. the factory machines.
A13: How prices work
A14: Import Price | B14: Base importer price (wholesalePrice). What you actually pay = base x that product's market price index (moves with shortage/surplus market events) x the difficulty market multiplier. Purchasing agents can get a discount on top.
A15: Avg Selling Price | B15: The game's default market price for the product (defaultMarketPrice). The optimal price the game suggests in a neighborhood = this x that neighborhood's average price index (+30% if you have a monopoly on the product there).
A16: Raw materials | B16: Raw materials are not sold to customers, so their selling price is left blank. (The game data holds placeholder values such as $0.01 or $10 for them.)
A17: Factory output | B17: Each recipe runs once per in-game hour per staffed workstation. Output = recipe amount x (factory-worker skill / 2 + 50)%, so 50% at skill 0 and 100% at skill 100; ingredient usage is the full recipe amount.
A18: Importer caps | B18: Max Import Order / Importer / Week is the per-importer weekly amount for that product. Imports are delivered on Mondays.
A19: "*" importers | B19: Items marked * are only sold by that importer when the new-game setting "all products available from importers" is on (expensive clothing, expensive jewelry, phones, smartwatches).
A21: Colour key | B21: Blue text = values taken straight from the game data. Black = formulas. Green = formulas pulling from another sheet.
